Workbook
Name UPDATE: 'Data Sheet'!$E$1

Sheet Profit & Loss
A1: ='Data Sheet'!B1 -> TATA CONSULTANCY SERVICES LTD | H1: =UPDATE | M1: SCREENER.IN
A3: Narration | B3: ='Data Sheet'!B16 -> 42825 | C3: ='Data Sheet'!C16 -> 43190 | D3: ='Data Sheet'!D16 -> 43555 | E3: ='Data Sheet'!E16 -> 43921 | F3: ='Data Sheet'!F16 -> 44286 | G3: ='Data Sheet'!G16 -> 44651 | H3: ='Data Sheet'!H16 -> 45016 | I3: ='Data Sheet'!I16 -> 45382 | ... K3: ='Data Sheet'!K16 -> 46112 | L3: Trailing | M3: Best Case | N3: Worst Case
A4: Sales | B4: ='Data Sheet'!B17 -> 117966 | C4: ='Data Sheet'!C17 -> 123104 | D4: ='Data Sheet'!D17 -> 146463 | E4: ='Data Sheet'!E17 -> 156949 | F4: ='Data Sheet'!F17 -> 164177 | G4: ='Data Sheet'!G17 -> 191754 | H4: ='Data Sheet'!H17 -> 225458 | I4: ='Data Sheet'!I17 -> 240893 | ... K4: ='Data Sheet'!K17 -> 267021 | L4: =SUM(Quarters!H4:K4) -> 275859 | M4: =$K4+M23*K4 -> 282513.15 | N4: =$K4+N23*L4 -> 279658.76
A5: Expenses | B5: =SUM('Data Sheet'!B18,'Data Sheet'!B20:B24, -1*'Data Sheet'!B19) -> 85655 | C5: =SUM('Data Sheet'!C18,'Data Sheet'!C20:C24, -1*'Data Sheet'!C19) -> 90588 | D5: =SUM('Data Sheet'!D18,'Data Sheet'!D20:D24, -1*'Data Sheet'!D19) -> 106957 | E5: =SUM('Data Sheet'!E18,'Data Sheet'!E20:E24, -1*'Data Sheet'!E19) -> 114840 | F5: =SUM('Data Sheet'!F18,'Data Sheet'!F20:F24, -1*'Data Sheet'!F19) -> 117631 | G5: =SUM('Data Sheet'!G18,'Data Sheet'!G20:G24, -1*'Data Sheet'!G19) -> 138697 | H5: =SUM('Data Sheet'!H18,'Data Sheet'!H20:H24, -1*'Data Sheet'!H19) -> 166199 | I5: =SUM('Data Sheet'!I18,'Data Sheet'!I20:I24, -1*'Data Sheet'!I19) -> 176597 | ... K5: =SUM('Data Sheet'!K18,'Data Sheet'!K20:K24, -1*'Data Sheet'!K19) -> 194623 | L5: =SUM(Quarters!H5:K5) -> 201780 | M5: =M4-M6 -> 206647.25 | N5: =N4-N6 -> 204873.92
A6: Operating Profit | B6: =B4-B5 -> 32311 | C6: =C4-C5 -> 32516 | D6: =D4-D5 -> 39506 | E6: =E4-E5 -> 42109 | F6: =F4-F5 -> 46546 | G6: =G4-G5 -> 53057 | H6: =H4-H5 -> 59259 | I6: =I4-I5 -> 64296 | ... K6: =K4-K5 -> 72398 | L6: =SUM(Quarters!H6:K6) -> 74079 | M6: =M4*M24 -> 75865.902 | N6: =N4*N24 -> 74784.84
A7: Other Income | B7: ='Data Sheet'!B25 -> 4221 | C7: ='Data Sheet'!C25 -> 3642 | D7: ='Data Sheet'!D25 -> 4311 | E7: ='Data Sheet'!E25 -> 4592 | F7: ='Data Sheet'!F25 -> 1916 | G7: ='Data Sheet'!G25 -> 4018 | H7: ='Data Sheet'!H25 -> 3449 | I7: ='Data Sheet'!I25 -> 3464 | ... K7: ='Data Sheet'!K25 -> -124 | L7: =SUM(Quarters!H7:K7) -> -884 | M7: 0 | N7: 0
A8: Depreciation | B8: ='Data Sheet'!B26 -> 1987 | C8: ='Data Sheet'!C26 -> 2014 | D8: ='Data Sheet'!D26 -> 2056 | E8: ='Data Sheet'!E26 -> 3529 | F8: ='Data Sheet'!F26 -> 4065 | G8: ='Data Sheet'!G26 -> 4604 | H8: ='Data Sheet'!H26 -> 5022 | I8: ='Data Sheet'!I26 -> 4985 | ... K8: ='Data Sheet'!K26 -> 5560 | L8: =SUM(Quarters!H8:K8) -> 5438 | M8: =+$L8 -> 5438 | N8: =+$L8 -> 5438
A9: Interest | B9: ='Data Sheet'!B27 -> 32 | C9: ='Data Sheet'!C27 -> 52 | D9: ='Data Sheet'!D27 -> 198 | E9: ='Data Sheet'!E27 -> 924 | F9: ='Data Sheet'!F27 -> 637 | G9: ='Data Sheet'!G27 -> 784 | H9: ='Data Sheet'!H27 -> 779 | I9: ='Data Sheet'!I27 -> 778 | ... K9: ='Data Sheet'!K27 -> 1227 | L9: =SUM(Quarters!H9:K9) -> 1305 | M9: =+$L9 -> 1305 | N9: =+$L9 -> 1305
A10: Profit before tax | B10: ='Data Sheet'!B28 -> 34513 | C10: ='Data Sheet'!C28 -> 34092 | D10: ='Data Sheet'!D28 -> 41563 | E10: ='Data Sheet'!E28 -> 42248 | F10: ='Data Sheet'!F28 -> 43760 | G10: ='Data Sheet'!G28 -> 51687 | H10: ='Data Sheet'!H28 -> 56907 | I10: ='Data Sheet'!I28 -> 61997 | ... K10: ='Data Sheet'!K28 -> 65487 | L10: =SUM(Quarters!H10:K10) -> 66452 | M10: =M6+M7-SUM(M8:M9) -> 69122.902 | N10: =N6+N7-SUM(N8:N9) -> 68041.84
A11: Tax | B11: ='Data Sheet'!B29 -> 8156 | C11: ='Data Sheet'!C29 -> 8212 | D11: ='Data Sheet'!D29 -> 10001 | E11: ='Data Sheet'!E29 -> 9801 | F11: ='Data Sheet'!F29 -> 11198 | G11: ='Data Sheet'!G29 -> 13238 | H11: ='Data Sheet'!H29 -> 14604 | I11: ='Data Sheet'!I29 -> 15898 | ... K11: ='Data Sheet'!K29 -> 16033 | L11: =SUM(Quarters!H11:K11) -> 16397 | M11: =IF($L10>0,$L11/$L10,0) -> 0.24674953 | N11: =IF($L10>0,$L11/$L10,0) -> 0.24674953
A12: Net profit | B12: ='Data Sheet'!B30 -> 26289 | C12: ='Data Sheet'!C30 -> 25826 | D12: ='Data Sheet'!D30 -> 31472 | E12: ='Data Sheet'!E30 -> 32340 | F12: ='Data Sheet'!F30 -> 32430 | G12: ='Data Sheet'!G30 -> 38327 | H12: ='Data Sheet'!H30 -> 42147 | I12: ='Data Sheet'!I30 -> 45908 | ... K12: ='Data Sheet'!K30 -> 49210 | L12: =SUM(Quarters!H12:K12) -> 49799 | M12: =M10-M11*M10 -> 52066.858 | N12: =N10-N11*N10 -> 51252.548
A13: EPS | B13: =IF('Data Sheet'!B93>0,B12/'Data Sheet'!B93,0) -> 66.708112 | C13: =IF('Data Sheet'!C93>0,C12/'Data Sheet'!C93,0) -> 67.455467 | D13: =IF('Data Sheet'!D93>0,D12/'Data Sheet'!D93,0) -> 83.871655 | E13: =IF('Data Sheet'!E93>0,E12/'Data Sheet'!E93,0) -> 86.184842 | F13: =IF('Data Sheet'!F93>0,F12/'Data Sheet'!F93,0) -> 87.669974 | G13: =IF('Data Sheet'!G93>0,G12/'Data Sheet'!G93,0) -> 104.74434 | H13: =IF('Data Sheet'!H93>0,H12/'Data Sheet'!H93,0) -> 115.18406 | I13: =IF('Data Sheet'!I93>0,I12/'Data Sheet'!I93,0) -> 126.88428 | ... K13: =IF('Data Sheet'!K93>0,K12/'Data Sheet'!K93,0) -> 136.01061 | L13: =IF('Data Sheet'!$B6>0,'Profit & Loss'!L12/'Data Sheet'!$B6,0) -> 137.639 | M13: =IF('Data Sheet'!$B6>0,'Profit & Loss'!M12/'Data Sheet'!$B6,0) -> 143.90712 | N13: =IF('Data Sheet'!$B6>0,'Profit & Loss'!N12/'Data Sheet'!$B6,0) -> 141.65645
A14: Price to earning | B14: =IF(B15>0,B15/B13,"") -> 18.227168 | C14: =IF(C15>0,C15/C13,"") -> 21.118822 | D14: =IF(D15>0,D15/D13,"") -> 23.865631 | E14: =IF(E15>0,E15/E13,"") -> 21.188181 | F14: =IF(F15>0,F15/F13,"") -> 36.247872 | G14: =IF(G15>0,G15/G13,"") -> 35.705511 | H14: =IF(H15>0,H15/H13,"") -> 27.832844 | I14: =IF(I15>0,I15/I13,"") -> 30.549885 | ... K14: =IF(K15>0,K15/K13,"") -> 17.343499 | L14: =IF(L13>0,L15/L13,0) -> 16.811005 | M14: =M25 -> 22.894226 | N14: =N25 -> 16.811005
A15: Price | B15: ='Data Sheet'!B90 -> 1215.9 | C15: ='Data Sheet'!C90 -> 1424.58 | D15: ='Data Sheet'!D90 -> 2001.65 | E15: ='Data Sheet'!E90 -> 1826.1 | F15: ='Data Sheet'!F90 -> 3177.85 | G15: ='Data Sheet'!G90 -> 3739.95 | H15: ='Data Sheet'!H90 -> 3205.9 | I15: ='Data Sheet'!I90 -> 3876.3 | ... K15: ='Data Sheet'!K90 -> 2358.9 | L15: ='Data Sheet'!B8 -> 2313.85 | M15: =M13*M14 -> 3294.642 | N15: =N13*N14 -> 2381.3873
A17: RATIOS:
A18: Dividend Payout | B18: =IF('Data Sheet'!B30>0, 'Data Sheet'!B31/'Data Sheet'!B30, 0) -> 0.35220054 | C18: =IF('Data Sheet'!C30>0, 'Data Sheet'!C31/'Data Sheet'!C30, 0) -> 0.36978239 | D18: =IF('Data Sheet'!D30>0, 'Data Sheet'!D31/'Data Sheet'!D30, 0) -> 0.3574606 | E18: =IF('Data Sheet'!E30>0, 'Data Sheet'!E31/'Data Sheet'!E30, 0) -> 0.84647495 | F18: =IF('Data Sheet'!F30>0, 'Data Sheet'!F31/'Data Sheet'!F30, 0) -> 0.43354918 | G18: =IF('Data Sheet'!G30>0, 'Data Sheet'!G31/'Data Sheet'!G30, 0) -> 0.41062436 | H18: =IF('Data Sheet'!H30>0, 'Data Sheet'!H31/'Data Sheet'!H30, 0) -> 0.99864759 | I18: =IF('Data Sheet'!I30>0, 'Data Sheet'!I31/'Data Sheet'!I30, 0) -> 0.57562952 | ... K18: =IF('Data Sheet'!K30>0, 'Data Sheet'!K31/'Data Sheet'!K30, 0) -> 0.80918512
A19: OPM | B19: =IF(B6>0,B6/B4,0) -> 0.27390095 | C19: =IF(C6>0,C6/C4,0) -> 0.26413439 | D19: =IF(D6>0,D6/D4,0) -> 0.26973365 | E19: =IF(E6>0,E6/E4,0) -> 0.26829734 | F19: =IF(F6>0,F6/F4,0) -> 0.28351109 | G19: =IF(G6>0,G6/G4,0) -> 0.27669305 | H19: =IF(H6>0,H6/H4,0) -> 0.26283831 | I19: =IF(I6>0,I6/I4,0) -> 0.26690688 | ... L19: =IF(L6>0,L6/L4,0) -> 0.26853936
G22: TRENDS: | H22: 10 YEARS | I22: 7 YEARS | J22: 5 YEARS | K22: 3 YEARS | L22: RECENT | M22: BEST | N22: WORST
G23: Sales Growth | H23: =IF(B4=0,"",POWER($K4/B4,1/9)-1) -> 0.095017227 | I23: =IF(D4=0,"",POWER($K4/D4,1/7)-1) -> 0.089581302 | J23: =IF(F4=0,"",POWER($K4/F4,1/5)-1) -> 0.10216501 | K23: =IF(H4=0,"",POWER($K4/H4, 1/3)-1) -> 0.058018486 | L23: =IF(ISERROR(MAX(IF(J4=0,"",(K4-J4)/J4),IF(K4=0,"",(L4-K4)/K4))),"",MAX(IF(J4=0,"",(K4-J4)/J4),IF(K4=0,"",(L4-K4)/K4))) -> 0.04581238 | M23: =MAX(K23:L23) -> 0.058018486 | N23: =MIN(H23:L23) -> 0.04581238
G24: OPM | H24: =IF(SUM(B4:$K$4)=0,"",SUMPRODUCT(B19:$K$19,B4:$K$4)/SUM(B4:$K$4)) -> 0.26965358 | I24: =IF(SUM(E4:$K$4)=0,"",SUMPRODUCT(E19:$K$19,E4:$K$4)/SUM(E4:$K$4)) -> 0.26976457 | J24: =IF(SUM(G4:$K$4)=0,"",SUMPRODUCT(G19:$K$19,G4:$K$4)/SUM(G4:$K$4)) -> 0.26804778 | K24: =IF(SUM(I4:$K$4)=0, "", SUMPRODUCT(I19:$K$19,I4:$K$4)/SUM(I4:$K$4)) -> 0.26741462 | L24: =L19 -> 0.26853936 | M24: =MAX(K24:L24) -> 0.26853936 | N24: =MIN(H24:L24) -> 0.26741462
G25: Price to Earning | H25: =IF(ISERROR(AVERAGEIF(B14:$L14,">0")),"",AVERAGEIF(B14:$L14,">0")) -> 25.069357 | I25: =IF(ISERROR(AVERAGEIF(E14:$L14,">0")),"",AVERAGEIF(E14:$L14,">0")) -> 26.568914 | J25: =IF(ISERROR(AVERAGEIF(G14:$L14,">0")),"",AVERAGEIF(G14:$L14,">0")) -> 25.852543 | K25: =IF(ISERROR(AVERAGEIF(I14:$L14,">0")),"",AVERAGEIF(I14:$L14,">0")) -> 22.894226 | L25: =L14 -> 16.811005 | M25: =MAX(K25:L25) -> 22.894226 | N25: =MIN(H25:L25) -> 16.811005

Sheet Quarters
A1: ='Profit & Loss'!A1 -> TATA CONSULTANCY SERVICES LTD | E1: =UPDATE | J1: SCREENER.IN
A3: Narration | B3: ='Data Sheet'!B41 -> 45382 | C3: ='Data Sheet'!C41 -> 45473 | D3: ='Data Sheet'!D41 -> 45565 | E3: ='Data Sheet'!E41 -> 45657 | F3: ='Data Sheet'!F41 -> 45747 | G3: ='Data Sheet'!G41 -> 45838 | H3: ='Data Sheet'!H41 -> 45930 | I3: ='Data Sheet'!I41 -> 46022 | ... K3: ='Data Sheet'!K41 -> 46203
A4: Sales | B4: ='Data Sheet'!B42 -> 61237 | C4: ='Data Sheet'!C42 -> 62613 | D4: ='Data Sheet'!D42 -> 64259 | E4: ='Data Sheet'!E42 -> 63973 | F4: ='Data Sheet'!F42 -> 64479 | G4: ='Data Sheet'!G42 -> 63437 | H4: ='Data Sheet'!H42 -> 65799 | I4: ='Data Sheet'!I42 -> 67087 | ... K4: ='Data Sheet'!K42 -> 72275
A5: Expenses | B5: ='Data Sheet'!B43 -> 44073 | C5: ='Data Sheet'!C43 -> 45951 | D5: ='Data Sheet'!D43 -> 47528 | E5: ='Data Sheet'!E43 -> 46939 | F5: ='Data Sheet'!F43 -> 47499 | G5: ='Data Sheet'!G43 -> 46562 | H5: ='Data Sheet'!H43 -> 47821 | I5: ='Data Sheet'!I43 -> 48818 | ... K5: ='Data Sheet'!K43 -> 53719
A6: Operating Profit | B6: ='Data Sheet'!B50 -> 17164 | C6: ='Data Sheet'!C50 -> 16662 | D6: ='Data Sheet'!D50 -> 16731 | E6: ='Data Sheet'!E50 -> 17034 | F6: ='Data Sheet'!F50 -> 16980 | G6: ='Data Sheet'!G50 -> 16875 | H6: ='Data Sheet'!H50 -> 17978 | I6: ='Data Sheet'!I50 -> 18269 | ... K6: ='Data Sheet'!K50 -> 18556
A7: Other Income | B7: ='Data Sheet'!B44 -> 1157 | C7: ='Data Sheet'!C44 -> 962 | D7: ='Data Sheet'!D44 -> 729 | E7: ='Data Sheet'!E44 -> 1243 | F7: ='Data Sheet'!F44 -> 1028 | G7: ='Data Sheet'!G44 -> 1660 | H7: ='Data Sheet'!H44 -> -268 | I7: ='Data Sheet'!I44 -> -2273 | ... K7: ='Data Sheet'!K44 -> 900
A8: Depreciation | B8: ='Data Sheet'!B45 -> 1246 | C8: ='Data Sheet'!C45 -> 1220 | D8: ='Data Sheet'!D45 -> 1266 | E8: ='Data Sheet'!E45 -> 1377 | F8: ='Data Sheet'!F45 -> 1379 | G8: ='Data Sheet'!G45 -> 1361 | H8: ='Data Sheet'!H45 -> 1413 | I8: ='Data Sheet'!I45 -> 1380 | ... K8: ='Data Sheet'!K45 -> 1239
A9: Interest | B9: ='Data Sheet'!B46 -> 226 | C9: ='Data Sheet'!C46 -> 173 | D9: ='Data Sheet'!D46 -> 162 | E9: ='Data Sheet'!E46 -> 234 | F9: ='Data Sheet'!F46 -> 227 | G9: ='Data Sheet'!G46 -> 195 | H9: ='Data Sheet'!H46 -> 229 | I9: ='Data Sheet'!I46 -> 538 | ... K9: ='Data Sheet'!K46 -> 273
A10: Profit before tax | B10: ='Data Sheet'!B47 -> 16849 | C10: ='Data Sheet'!C47 -> 16231 | D10: ='Data Sheet'!D47 -> 16032 | E10: ='Data Sheet'!E47 -> 16666 | F10: ='Data Sheet'!F47 -> 16402 | G10: ='Data Sheet'!G47 -> 16979 | H10: ='Data Sheet'!H47 -> 16068 | I10: ='Data Sheet'!I47 -> 14078 | ... K10: ='Data Sheet'!K47 -> 17944
A11: Tax | B11: ='Data Sheet'!B48 -> 4347 | C11: ='Data Sheet'!C48 -> 4126 | D11: ='Data Sheet'!D48 -> 4077 | E11: ='Data Sheet'!E48 -> 4222 | F11: ='Data Sheet'!F48 -> 4109 | G11: ='Data Sheet'!G48 -> 4160 | H11: ='Data Sheet'!H48 -> 3937 | I11: ='Data Sheet'!I48 -> 3358 | ... K11: ='Data Sheet'!K48 -> 4524
A12: Net profit | B12: ='Data Sheet'!B49 -> 12434 | C12: ='Data Sheet'!C49 -> 12040 | D12: ='Data Sheet'!D49 -> 11909 | E12: ='Data Sheet'!E49 -> 12380 | F12: ='Data Sheet'!F49 -> 12224 | G12: ='Data Sheet'!G49 -> 12760 | H12: ='Data Sheet'!H49 -> 12075 | I12: ='Data Sheet'!I49 -> 10657 | ... K12: ='Data Sheet'!K49 -> 13349
A14: OPM | B14: =IF(B4>0,B6/B4,"") -> 0.28028806 | C14: =IF(C4>0,C6/C4,"") -> 0.26611087 | D14: =IF(D4>0,D6/D4,"") -> 0.2603682 | E14: =IF(E4>0,E6/E4,"") -> 0.26626858 | F14: =IF(F4>0,F6/F4,"") -> 0.26334155 | G14: =IF(G4>0,G6/G4,"") -> 0.26601195 | H14: =IF(H4>0,H6/H4,"") -> 0.27322604 | I14: =IF(I4>0,I6/I4,"") -> 0.27231803 | ... K14: =IF(K4>0,K6/K4,"") -> 0.25674161

Sheet Sheet3
C2: PROFITABILITY RATIO
C4: Ratio | D4: Formula | E4: FY 2023–24 | F4: FY 2024–25 | G4: FY 2025–26
C5: Net Profit Margin | D5: Net Profit ÷ Revenue × 100 | E5: 0.193 | F5: 0.19 | G5: 0.198
C6: Operating Margin | D6: Operating Profit ÷ Revenue × 100 | E6: 0.246 | F6: 0.243 | G6: 0.25
C7: Return on Equity (ROE) | D7: Net Profit ÷ Average Equity × 100 | E7: 0.513 | F7: 0.522 | G7: 0.514
C8: Return on Assets (ROA) | D8: Net Profit ÷ Average Total Assets × 100 | E8: ≈31.4% | F8: ≈31.9% | G8: ≈28.9%
C9: EPS | D9: Profit attributable to shareholders ÷ No. of shares | E9: 127.74 | F9: 134.19 | G9: 145.99

Sheet Sheet4

Sheet Balance Sheet
A1: ='Profit & Loss'!A1 -> TATA CONSULTANCY SERVICES LTD | E1: =UPDATE | G1: SCREENER.IN
A3: Narration | B3: ='Data Sheet'!B56 -> 42825 | C3: ='Data Sheet'!C56 -> 43190 | D3: ='Data Sheet'!D56 -> 43555 | E3: ='Data Sheet'!I56 -> 45382 | F3: ='Data Sheet'!J56 -> 45747 | G3: ='Data Sheet'!K56 -> 46112
A4: Equity Share Capital | B4: ='Data Sheet'!B57 -> 197 | C4: ='Data Sheet'!C57 -> 191 | D4: ='Data Sheet'!D57 -> 375 | E4: ='Data Sheet'!I57 -> 362 | F4: ='Data Sheet'!J57 -> 362 | G4: ='Data Sheet'!K57 -> 362
A5: Reserves | B5: ='Data Sheet'!B58 -> 86017 | C5: ='Data Sheet'!C58 -> 84937 | D5: ='Data Sheet'!D58 -> 89071 | E5: ='Data Sheet'!I58 -> 90127 | F5: ='Data Sheet'!J58 -> 94394 | G5: ='Data Sheet'!K58 -> 106878
A6: Borrowings | B6: ='Data Sheet'!B59 -> 289 | C6: ='Data Sheet'!C59 -> 247 | D6: ='Data Sheet'!D59 -> 62 | E6: ='Data Sheet'!I59 -> 8021 | F6: ='Data Sheet'!J59 -> 9392 | G6: ='Data Sheet'!K59 -> 11283
A7: Other Liabilities | B7: ='Data Sheet'!B60 -> 15830 | C7: ='Data Sheet'!C60 -> 19751 | D7: ='Data Sheet'!D60 -> 24393 | E7: ='Data Sheet'!I60 -> 46962 | F7: ='Data Sheet'!J60 -> 54501 | G7: ='Data Sheet'!K60 -> 62644
A8: Total | B8: ='Data Sheet'!B61 -> 102333 | C8: ='Data Sheet'!C61 -> 105126 | D8: ='Data Sheet'!D61 -> 113901 | E8: ='Data Sheet'!I61 -> 145472 | F8: ='Data Sheet'!J61 -> 158649 | G8: ='Data Sheet'!K61 -> 181167
A10: Net Block | B10: ='Data Sheet'!B62 -> 11701 | C10: ='Data Sheet'!C62 -> 11973 | D10: ='Data Sheet'!D62 -> 12290 | E10: ='Data Sheet'!I62 -> 19604 | F10: ='Data Sheet'!J62 -> 23053 | G10: ='Data Sheet'!K62 -> 31343
A11: Capital Work in Progress | B11: ='Data Sheet'!B63 -> 1541 | C11: ='Data Sheet'!C63 -> 1278 | D11: ='Data Sheet'!D63 -> 963 | E11: ='Data Sheet'!I63 -> 1564 | F11: ='Data Sheet'!J63 -> 1546 | G11: ='Data Sheet'!K63 -> 2665
A12: Investments | B12: ='Data Sheet'!B64 -> 41980 | C12: ='Data Sheet'!C64 -> 36008 | D12: ='Data Sheet'!D64 -> 29330 | E12: ='Data Sheet'!I64 -> 31762 | F12: ='Data Sheet'!J64 -> 30964 | G12: ='Data Sheet'!K64 -> 33988
A13: Other Assets | B13: ='Data Sheet'!B65 -> 47111 | C13: ='Data Sheet'!C65 -> 55867 | D13: ='Data Sheet'!D65 -> 71318 | E13: ='Data Sheet'!I65 -> 92542 | F13: ='Data Sheet'!J65 -> 103086 | G13: ='Data Sheet'!K65 -> 113171
A14: Total | B14: ='Data Sheet'!B66 -> 102333 | C14: ='Data Sheet'!C66 -> 105126 | D14: ='Data Sheet'!D66 -> 113901 | E14: ='Data Sheet'!I66 -> 145472 | F14: ='Data Sheet'!J66 -> 158649 | G14: ='Data Sheet'!K66 -> 181167
A16: Working Capital | B16: =B13-B7 -> 31281 | C16: =C13-C7 -> 36116 | D16: =D13-D7 -> 46925 | E16: =E13-E7 -> 45580 | F16: =F13-F7 -> 48585 | G16: =G13-G7 -> 50527
A17: Debtors | B17: ='Data Sheet'!B67 -> 22617 | C17: ='Data Sheet'!C67 -> 24943 | D17: ='Data Sheet'!D67 -> 27346 | E17: ='Data Sheet'!I67 -> 53577 | F17: ='Data Sheet'!J67 -> 59046 | G17: ='Data Sheet'!K67 -> 67714
A18: Inventory | B18: ='Data Sheet'!B68 -> 21 | C18: ='Data Sheet'!C68 -> 26 | D18: ='Data Sheet'!D68 -> 10 | E18: ='Data Sheet'!I68 -> 28 | F18: ='Data Sheet'!J68 -> 21 | G18: ='Data Sheet'!K68 -> 29
A20: Debtor Days | B20: =IF('Profit & Loss'!B4>0,'Balance Sheet'!B17/('Profit & Loss'!B4/365),0) -> 69.979528 | C20: =IF('Profit & Loss'!C4>0,'Balance Sheet'!C17/('Profit & Loss'!C4/365),0) -> 73.955314 | D20: =IF('Profit & Loss'!D4>0,'Balance Sheet'!D17/('Profit & Loss'!D4/365),0) -> 68.148884 | E20: =IF('Profit & Loss'!I4>0,'Balance Sheet'!E17/('Profit & Loss'!I4/365),0) -> 81.179632 | F20: =IF('Profit & Loss'!J4>0,'Balance Sheet'!F17/('Profit & Loss'!J4/365),0) -> 84.409574 | G20: =IF('Profit & Loss'!K4>0,'Balance Sheet'!G17/('Profit & Loss'!K4/365),0) -> 92.560548
A21: Inventory Turnover | B21: =IF('Balance Sheet'!B18>0,'Profit & Loss'!B4/'Balance Sheet'!B18,0) -> 5617.4286 | C21: =IF('Balance Sheet'!C18>0,'Profit & Loss'!C4/'Balance Sheet'!C18,0) -> 4734.7692 | D21: =IF('Balance Sheet'!D18>0,'Profit & Loss'!D4/'Balance Sheet'!D18,0) -> 14646.3 | E21: =IF('Balance Sheet'!E18>0,'Profit & Loss'!I4/'Balance Sheet'!E18,0) -> 8603.3214 | F21: =IF('Balance Sheet'!F18>0,'Profit & Loss'!J4/'Balance Sheet'!F18,0) -> 12158.286 | G21: =IF('Balance Sheet'!G18>0,'Profit & Loss'!K4/'Balance Sheet'!G18,0) -> 9207.6207
A23: Return on Equity | B23: =IF(SUM('Balance Sheet'!B4:B5)>0,'Profit & Loss'!B12/SUM('Balance Sheet'!B4:B5),"") -> 0.30492727 | C23: =IF(SUM('Balance Sheet'!C4:C5)>0,'Profit & Loss'!C12/SUM('Balance Sheet'!C4:C5),"") -> 0.30337844 | D23: =IF(SUM('Balance Sheet'!D4:D5)>0,'Profit & Loss'!D12/SUM('Balance Sheet'!D4:D5),"") -> 0.35185475 | E23: =IF(SUM('Balance Sheet'!E4:E5)>0,'Profit & Loss'!I12/SUM('Balance Sheet'!E4:E5),"") -> 0.50733238 | F23: =IF(SUM('Balance Sheet'!F4:F5)>0,'Profit & Loss'!J12/SUM('Balance Sheet'!F4:F5),"") -> 0.51240027 | G23: =IF(SUM('Balance Sheet'!G4:G5)>0,'Profit & Loss'!K12/SUM('Balance Sheet'!G4:G5),"") -> 0.45887728
A24: Return on Capital Emp | C24: =IF((B4+B5+B6+C4+C5+C6)>0,('Profit & Loss'!C10+'Profit & Loss'!C9)*2/(B4+B5+B6+C4+C5+C6),"") -> 0.39730507 | D24: =IF((C4+C5+C6+D4+D5+D6)>0,('Profit & Loss'!D10+'Profit & Loss'!D9)*2/(C4+C5+C6+D4+D5+D6),"") -> 0.47758787 | E24: =IF((#REF!+#REF!+#REF!+E4+E5+E6)>0,('Profit & Loss'!I10+'Profit & Loss'!I9)*2/(#REF!+#REF!+#REF!+E4+E5+E6),"") -> #REF! | F24: =IF((E4+E5+E6+F4+F5+F6)>0,('Profit & Loss'!J10+'Profit & Loss'!J9)*2/(E4+E5+E6+F4+F5+F6),"") -> 0.65259699 | G24: =IF((F4+F5+F6+G4+G5+G6)>0,('Profit & Loss'!K10+'Profit & Loss'!K9)*2/(F4+F5+F6+G4+G5+G6),"") -> 0.59921588

Sheet Cash Flow
A1: ='Balance Sheet'!A1 -> TATA CONSULTANCY SERVICES LTD | E1: =UPDATE | J1: SCREENER.IN
A3: Particulars | B3: FY 2023–24 | C3: FY 2024–25 | D3: FY 2025–26
A4: Cash from Operating Activities | B4: 44338 | C4: 48908 | D4: 52094
A5: Cash from Investing Activities | B5: 6026 | C5: -2318 | D5: -12845
A6: Cash from Financing Activities | B6: -48536 | C6: -47438 | D6: -42133
A7: Net Cash Flow | B7: 1828 | C7: -848 | D7: -2884
A8: Opening Cash & Cash Equivalents | B8: 7123 | C8: 9016 | D8: 8342
A9: Closing Cash & Cash Equivalents | B9: 9016 | C9: 8342 | D9: 6417

Sheet Customization
A1: How to use it?
A3: You can customize this workbook as you want.
B4: You can add custom formating, add conditional formating, add your own formulas… do ANYTHING.
B5: Please don't edit the "Data Sheet" only.
A7: After customization, you can upload this back on Screener.
B8: Upload on: | C8: https://www.screener.in/excel/
A10: Download your customized workbooks now onwards.
B11: Now whenever you will "Export to excel" from Screener, it will export your customized file.
A14: TESTING:
B15: This is a testing feature currently.
B16: You can report any formula errors on the worksheet at: support@screener.in

Sheet Data Sheet
A1: COMPANY NAME | B1: TATA CONSULTANCY SERVICES LTD | E1: =IF(B2<>B3, "A NEW VERSION OF THE WORKSHEET IS AVAILABLE", "")
A2: LATEST VERSION | B2: 2.1 | E2: PLEASE DO NOT MAKE ANY CHANGES TO THIS SHEET
A3: CURRENT VERSION | B3: 2.1
A5: META
A6: Number of shares | B6: =IF(B9>0, B9/B8, 0) -> 361.80878
A7: Face Value | B7: 1
A8: Current Price | B8: 2313.85
A9: Market Capitalization | B9: 837171.24
A15: PROFIT & LOSS
A16: Report Date | B16: 42825 | C16: 43190 | D16: 43555 | E16: 43921 | F16: 44286 | G16: 44651 | H16: 45016 | I16: 45382 | J16: 45747 | K16: 46112
A17: Sales | B17: 117966 | C17: 123104 | D17: 146463 | E17: 156949 | F17: 164177 | G17: 191754 | H17: 225458 | I17: 240893 | J17: 255324 | K17: 267021
A18: Raw Material Cost | B18: 94 | C18: 86 | D18: 40 | E18: 18 | F18: 14 | G18: 29 | H18: 37 | I18: 42 | J18: 49 | K18: 43
A19: Change in Inventory | B19: 1
A20: Power and Fuel
A21: Other Mfr. Exp | B21: 2715 | C21: 2614 | D21: 2230 | E21: 1887 | F21: 1448 | G21: 1134 | H21: 1844 | I21: 3660 | J21: 11599 | K21: 4356
A22: Employee Cost | B22: 61621 | C22: 66396 | D22: 78246 | E22: 85952 | F22: 91814 | G22: 107554 | H22: 127522 | I22: 140131 | J22: 145788 | K22: 154994
A23: Selling and admin | B23: 16392 | C23: 16808 | D23: 20387 | E23: 20527 | F23: 18322 | G23: 23187 | H23: 28913 | I23: 24151 | J23: 20729 | K23: 24434
A24: Other Expenses | B24: 4834 | C24: 4684 | D24: 6054 | E24: 6456 | F24: 6033 | G24: 6793 | H24: 7883 | I24: 8613 | J24: 9752 | K24: 10796
A25: Other Income | B25: 4221 | C25: 3642 | D25: 4311 | E25: 4592 | F25: 1916 | G25: 4018 | H25: 3449 | I25: 3464 | J25: 3962 | K25: -124
A26: Depreciation | B26: 1987 | C26: 2014 | D26: 2056 | E26: 3529 | F26: 4065 | G26: 4604 | H26: 5022 | I26: 4985 | J26: 5242 | K26: 5560
A27: Interest | B27: 32 | C27: 52 | D27: 198 | E27: 924 | F27: 637 | G27: 784 | H27: 779 | I27: 778 | J27: 796 | K27: 1227
A28: Profit before tax | B28: 34513 | C28: 34092 | D28: 41563 | E28: 42248 | F28: 43760 | G28: 51687 | H28: 56907 | I28: 61997 | J28: 65331 | K28: 65487
A29: Tax | B29: 8156 | C29: 8212 | D29: 10001 | E29: 9801 | F29: 11198 | G29: 13238 | H29: 14604 | I29: 15898 | J29: 16534 | K29: 16033
A30: Net profit | B30: 26289 | C30: 25826 | D30: 31472 | E30: 32340 | F30: 32430 | G30: 38327 | H30: 42147 | I30: 45908 | J30: 48553 | K30: 49210
A31: Dividend Amount | B31: 9259 | C31: 9550 | D31: 11250 | E31: 27375 | F31: 14060 | G31: 15738 | H31: 42090 | I31: 26426 | J31: 45612 | K31: 39820
A40: Quarters
A41: Report Date | B41: 45382 | C41: 45473 | D41: 45565 | E41: 45657 | F41: 45747 | G41: 45838 | H41: 45930 | I41: 46022 | J41: 46112 | K41: 46203
A42: Sales | B42: 61237 | C42: 62613 | D42: 64259 | E42: 63973 | F42: 64479 | G42: 63437 | H42: 65799 | I42: 67087 | J42: 70698 | K42: 72275
A43: Expenses | B43: 44073 | C43: 45951 | D43: 47528 | E43: 46939 | F43: 47499 | G43: 46562 | H43: 47821 | I43: 48818 | J43: 51422 | K43: 53719
A44: Other Income | B44: 1157 | C44: 962 | D44: 729 | E44: 1243 | F44: 1028 | G44: 1660 | H44: -268 | I44: -2273 | J44: 757 | K44: 900
A45: Depreciation | B45: 1246 | C45: 1220 | D45: 1266 | E45: 1377 | F45: 1379 | G45: 1361 | H45: 1413 | I45: 1380 | J45: 1406 | K45: 1239
A46: Interest | B46: 226 | C46: 173 | D46: 162 | E46: 234 | F46: 227 | G46: 195 | H46: 229 | I46: 538 | J46: 265 | K46: 273
A47: Profit before tax | B47: 16849 | C47: 16231 | D47: 16032 | E47: 16666 | F47: 16402 | G47: 16979 | H47: 16068 | I47: 14078 | J47: 18362 | K47: 17944
A48: Tax | B48: 4347 | C48: 4126 | D48: 4077 | E48: 4222 | F48: 4109 | G48: 4160 | H48: 3937 | I48: 3358 | J48: 4578 | K48: 4524
A49: Net profit | B49: 12434 | C49: 12040 | D49: 11909 | E49: 12380 | F49: 12224 | G49: 12760 | H49: 12075 | I49: 10657 | J49: 13718 | K49: 13349
A50: Operating Profit | B50: 17164 | C50: 16662 | D50: 16731 | E50: 17034 | F50: 16980 | G50: 16875 | H50: 17978 | I50: 18269 | J50: 19276 | K50: 18556
A55: BALANCE SHEET
A56: Report Date | B56: 42825 | C56: 43190 | D56: 43555 | E56: 43921 | F56: 44286 | G56: 44651 | H56: 45016 | I56: 45382 | J56: 45747 | K56: 46112
A57: Equity Share Capital | B57: 197 | C57: 191 | D57: 375 | E57: 375 | F57: 370 | G57: 366 | H57: 366 | I57: 362 | J57: 362 | K57: 362
A58: Reserves | B58: 86017 | C58: 84937 | D58: 89071 | E58: 83751 | F58: 86063 | G58: 88773 | H58: 90058 | I58: 90127 | J58: 94394 | K58: 106878
...

Sheet Sheet5
C2: LIQUIDITY RATIO
B5: Ratio | C5: Formula | D5: FY 2023–24 | E5: FY 2024–25 | F5: FY 2025–26
B6: Current Ratio | C6: Current Assets ÷ Current Liabilities | D6: 2.45 | E6: 2.32 | F6: 2.23
B7: Quick Ratio | C7: (Current Assets − Inventory) ÷ Current Liabilities | D7: 2.45 | E7: 2.32 | F7: 2.23
B8: Cash Ratio | C8: Cash & Cash Equivalents ÷ Current Liabilities | D8: 0.2 | E8: 0.16 | F8: 0.11

Sheet Sheet10
D2: PROFITABILITY RATIO TRENDS
C5: RATIO | D5: FY 2023–24 | E5: FY 2024–25 | F5: FY 2025–26
C6: Net Profit Margin | D6: 0.193 | E6: 0.19 | F6: 0.198
C7: Operating Margin | D7: 0.246 | E7: 0.243 | F7: 0.25
C8: Return on Equity (ROE) | D8: 0.513 | E8: 0.522 | F8: 0.514

Sheet Sheet6
D2: SOLVENCY RATIO
C5: Solvency Ratio | D5: Formula | E5: FY 2023–24 | F5: FY 2024–25 | G5: FY 2025–26
C6: Debt-to-Equity Ratio | D6: Total Debt ÷ Total Equity | E6: 0.11 | F6: 0.1 | G6: 0.02
C7: Interest Coverage Ratio | D7: EBIT ÷ Interest Expense | E7: 80.66 | F7: 82.07 | G7: 54.39
C8: Debt Ratio | D8: Total Debt ÷ Total Assets × 100 | E8: 0.069 | F8: 0.0588 | G8: 0.0125

Sheet Sheet7
C3: EFFICIENCY RATIO
B6: Efficiency Ratio | C6: Formula | D6: FY 2023–24 | E6: FY 2024–25 | F6: FY 2025–26
B7: Asset Turnover Ratio | C7: Revenue from Operations ÷ Average Total Assets | D7: 1.63 | E7: 1.67 | F7: 1.56
B8: Inventory Turnover Ratio | C8: Cost of Services ÷ Average Inventory | D8: 5000 | E8: 6000 | F8: 5500
B9: Receivables Turnover Ratio | C9: Revenue from Operations ÷ Average Trade Receivables | D9: 4.5 | E9: 4.4 | F9: 4.1

Sheet Sheet8
C2: YEAR ON YEAR GROWTH
C4: TCS YoY Growth (%) | D4: FY 2023-24 | E4: FY 2024-25 | F4: FY 2025-26
C5: Revenue | D5: 0.0685 | E5: 0.0599 | F5: 0.0458
C6: Operating Profit | D6: 0.085 | E6: 0.0484 | F6: 0.074
C7: Net Profit | D7: 0.0897 | E7: 0.0585 | F7: 0.0135
C8: Total Assets | D8: 0.0195 | E8: 0.09 | F8: 0.1425
C9: Total Equity | D9: 0.0012 | E9: 0.0488 | F9: 0.1326
C10: Operating Cash Flow | D10: 0.0565 | E10: 0.1031 | F10: 0.0651

Sheet Sheet9
D3: REVENUE & NET PROFIT TREND
C9: Particular | D9: FY 2023–24 | E9: FY 2024–25 | F9: FY 2025–26
C10: Revenue from Operations | D10: 240893 | E10: 255324 | F10: 267021
C11: Profit for the Year | D11: 46099 | E11: 48797 | F11: 49454

Sheet Sheet11
D4: DEBT TO EQUITY & CURRENT RATIO ANALYSIS
C8: Ratio | D8: Formula | E8: FY 2023–24 | F8: FY 2024–25 | G8: FY 2025–26
C9: Current Ratio | D9: Current Assets ÷ Current Liabilities | E9: 2.45 | F9: 2.32 | G9: 2.23
C10: Debt-to-Equity Ratio | D10: Total Debt ÷ Total Equity | E10: 0.11 | F10: 0.1 | G10: 0.02
